2019-06-14 17:28:58,002 (74679/MainThread) saws.saws ERROR - traceback: 'Traceback (most recent call last):\n  File "/usr/local/lib/python3.7/site-packages/saws/resources.py", line 230, in _query_resources\n    resource_list.query_resource()\n  File "/usr/local/lib/python3.7/site-packages/saws/resource/instance_ids.py", line 59, in query_resource\n    output = self._query_aws(self.QUERY)\n  File "/usr/local/lib/python3.7/site-packages/saws/resource/resource.py", line 98, in _query_aws\n    shell=True)\n  File "/usr/local/Cellar/python/3.7.3/Frameworks/Python.framework/Versions/3.7/lib/python3.7/subprocess.py", line 395, in check_output\n    **kwargs).stdout\n  File "/usr/local/Cellar/python/3.7.3/Frameworks/Python.framework/Versions/3.7/lib/python3.7/subprocess.py", line 487, in run\n    output=stdout, stderr=stderr)\nsubprocess.CalledProcessError: Command \'aws ec2 describe-instances --query "Reservations[].Instances[].[InstanceId]" --output text\' returned non-zero exit status 255.\n'
2019-06-14 17:28:59,559 (74679/MainThread) saws.saws ERROR - traceback: 'Traceback (most recent call last):\n  File "/usr/local/lib/python3.7/site-packages/saws/resources.py", line 230, in _query_resources\n    resource_list.query_resource()\n  File "/usr/local/lib/python3.7/site-packages/saws/resource/instance_tag_keys.py", line 60, in query_resource\n    output = self._query_aws(self.QUERY)\n  File "/usr/local/lib/python3.7/site-packages/saws/resource/resource.py", line 98, in _query_aws\n    shell=True)\n  File "/usr/local/Cellar/python/3.7.3/Frameworks/Python.framework/Versions/3.7/lib/python3.7/subprocess.py", line 395, in check_output\n    **kwargs).stdout\n  File "/usr/local/Cellar/python/3.7.3/Frameworks/Python.framework/Versions/3.7/lib/python3.7/subprocess.py", line 487, in run\n    output=stdout, stderr=stderr)\nsubprocess.CalledProcessError: Command \'aws ec2 describe-instances --filters "Name=tag-key,Values=*" --query Reservations[].Instances[].Tags[].Key --output text\' returned non-zero exit status 255.\n'
2019-06-14 17:29:01,116 (74679/MainThread) saws.saws ERROR - traceback: 'Traceback (most recent call last):\n  File "/usr/local/lib/python3.7/site-packages/saws/resources.py", line 230, in _query_resources\n    resource_list.query_resource()\n  File "/usr/local/lib/python3.7/site-packages/saws/resource/instance_tag_values.py", line 60, in query_resource\n    output = self._query_aws(self.QUERY)\n  File "/usr/local/lib/python3.7/site-packages/saws/resource/resource.py", line 98, in _query_aws\n    shell=True)\n  File "/usr/local/Cellar/python/3.7.3/Frameworks/Python.framework/Versions/3.7/lib/python3.7/subprocess.py", line 395, in check_output\n    **kwargs).stdout\n  File "/usr/local/Cellar/python/3.7.3/Frameworks/Python.framework/Versions/3.7/lib/python3.7/subprocess.py", line 487, in run\n    output=stdout, stderr=stderr)\nsubprocess.CalledProcessError: Command \'aws ec2 describe-instances --filters "Name=tag-value,Values=*" --query Reservations[].Instances[].Tags[].Value --output text\' returned non-zero exit status 255.\n'
2019-06-14 17:29:02,638 (74679/MainThread) saws.saws ERROR - traceback: 'Traceback (most recent call last):\n  File "/usr/local/lib/python3.7/site-packages/saws/resources.py", line 230, in _query_resources\n    resource_list.query_resource()\n  File "/usr/local/lib/python3.7/site-packages/saws/resource/bucket_names.py", line 58, in query_resource\n    super(BucketNames, self).query_resource()\n  File "/usr/local/lib/python3.7/site-packages/saws/resource/bucket.py", line 67, in query_resource\n    output = self._query_aws(self.QUERY)\n  File "/usr/local/lib/python3.7/site-packages/saws/resource/resource.py", line 98, in _query_aws\n    shell=True)\n  File "/usr/local/Cellar/python/3.7.3/Frameworks/Python.framework/Versions/3.7/lib/python3.7/subprocess.py", line 395, in check_output\n    **kwargs).stdout\n  File "/usr/local/Cellar/python/3.7.3/Frameworks/Python.framework/Versions/3.7/lib/python3.7/subprocess.py", line 487, in run\n    output=stdout, stderr=stderr)\nsubprocess.CalledProcessError: Command \'aws s3 ls\' returned non-zero exit status 255.\n'
2019-06-14 17:29:03,118 (74679/MainThread) saws.saws ERROR - traceback: 'Traceback (most recent call last):\n  File "/usr/local/lib/python3.7/site-packages/saws/resources.py", line 230, in _query_resources\n    resource_list.query_resource()\n  File "/usr/local/lib/python3.7/site-packages/saws/resource/bucket_uris.py", line 59, in query_resource\n    super(BucketUris, self).query_resource()\n  File "/usr/local/lib/python3.7/site-packages/saws/resource/bucket.py", line 67, in query_resource\n    output = self._query_aws(self.QUERY)\n  File "/usr/local/lib/python3.7/site-packages/saws/resource/resource.py", line 98, in _query_aws\n    shell=True)\n  File "/usr/local/Cellar/python/3.7.3/Frameworks/Python.framework/Versions/3.7/lib/python3.7/subprocess.py", line 395, in check_output\n    **kwargs).stdout\n  File "/usr/local/Cellar/python/3.7.3/Frameworks/Python.framework/Versions/3.7/lib/python3.7/subprocess.py", line 487, in run\n    output=stdout, stderr=stderr)\nsubprocess.CalledProcessError: Command \'aws s3 ls\' returned non-zero exit status 255.\n'
2019-06-21 19:14:41,761 (42298/Thread-21) saws.saws ERROR - traceback: 'Traceback (most recent call last):\n  File "/usr/local/lib/python3.7/site-packages/saws/completer.py", line 257, in _get_aws_cli_completions\n    self.aws_completer.complete(text, len(text))\n  File "/usr/local/lib/python3.7/site-packages/awscli/completer.py", line 133, in complete\n    choices = Completer().complete(cmdline, point)\n  File "/usr/local/lib/python3.7/site-packages/awscli/completer.py", line 36, in complete\n    current_arg = args[-1]\nIndexError: list index out of range\n'
